2024-03-04 11:40:27,512 INFO    StreamThr :6886 [internal.py:wandb_internal():86] W&B internal server running at pid: 6886, started at: 2024-03-04 11:40:27.511978
2024-03-04 11:40:27,517 DEBUG   HandlerThread:6886 [handler.py:handle_request():146] handle_request: status
2024-03-04 11:40:27,519 INFO    WriterThread:6886 [datastore.py:open_for_write():87] open: /home/sadbhawna/Desktop/cs6910_assignment1/wandb/run-20240304_114027-g770qtjx/run-g770qtjx.wandb
2024-03-04 11:40:27,519 DEBUG   SenderThread:6886 [sender.py:send():382] send: header
2024-03-04 11:40:27,524 DEBUG   SenderThread:6886 [sender.py:send():382] send: run
2024-03-04 11:40:32,525 DEBUG   HandlerThread:6886 [handler.py:handle_request():146] handle_request: keepalive
2024-03-04 11:40:37,526 DEBUG   HandlerThread:6886 [handler.py:handle_request():146] handle_request: keepalive
2024-03-04 11:40:42,527 DEBUG   HandlerThread:6886 [handler.py:handle_request():146] handle_request: keepalive
2024-03-04 11:40:47,528 DEBUG   HandlerThread:6886 [handler.py:handle_request():146] handle_request: keepalive
2024-03-04 11:40:52,530 DEBUG   HandlerThread:6886 [handler.py:handle_request():146] handle_request: keepalive
2024-03-04 11:40:57,531 DEBUG   HandlerThread:6886 [handler.py:handle_request():146] handle_request: keepalive
2024-03-04 11:41:02,532 DEBUG   HandlerThread:6886 [handler.py:handle_request():146] handle_request: keepalive
2024-03-04 11:41:07,534 DEBUG   HandlerThread:6886 [handler.py:handle_request():146] handle_request: keepalive
2024-03-04 11:41:12,535 DEBUG   HandlerThread:6886 [handler.py:handle_request():146] handle_request: keepalive
2024-03-04 11:41:17,537 DEBUG   HandlerThread:6886 [handler.py:handle_request():146] handle_request: keepalive
2024-03-04 11:41:22,538 DEBUG   HandlerThread:6886 [handler.py:handle_request():146] handle_request: keepalive
2024-03-04 11:41:27,540 DEBUG   HandlerThread:6886 [handler.py:handle_request():146] handle_request: keepalive
2024-03-04 11:41:30,956 INFO    SenderThread:6886 [retry.py:__call__():172] Retry attempt failed:
Traceback (most recent call last):
  File "/home/sadbhawna/anaconda3/lib/python3.11/site-packages/urllib3/connection.py", line 174, in _new_conn
    conn = connection.create_connection(
           ^^^^^^^^^^^^^^^^^^^^^^^^^^^^^
  File "/home/sadbhawna/anaconda3/lib/python3.11/site-packages/urllib3/util/connection.py", line 95, in create_connection
    raise err
  File "/home/sadbhawna/anaconda3/lib/python3.11/site-packages/urllib3/util/connection.py", line 85, in create_connection
    sock.connect(sa)
TimeoutError: timed out

During handling of the above exception, another exception occurred:

Traceback (most recent call last):
  File "/home/sadbhawna/anaconda3/lib/python3.11/site-packages/urllib3/connectionpool.py", line 714, in urlopen
    httplib_response = self._make_request(
                       ^^^^^^^^^^^^^^^^^^^
  File "/home/sadbhawna/anaconda3/lib/python3.11/site-packages/urllib3/connectionpool.py", line 403, in _make_request
    self._validate_conn(conn)
  File "/home/sadbhawna/anaconda3/lib/python3.11/site-packages/urllib3/connectionpool.py", line 1053, in _validate_conn
    conn.connect()
  File "/home/sadbhawna/anaconda3/lib/python3.11/site-packages/urllib3/connection.py", line 363, in connect
    self.sock = conn = self._new_conn()
                       ^^^^^^^^^^^^^^^^
  File "/home/sadbhawna/anaconda3/lib/python3.11/site-packages/urllib3/connection.py", line 179, in _new_conn
    raise ConnectTimeoutError(
urllib3.exceptions.ConnectTimeoutError: (<urllib3.connection.HTTPSConnection object at 0x7f9df5d026d0>, 'Connection to api.wandb.ai timed out. (connect timeout=20)')

During handling of the above exception, another exception occurred:

Traceback (most recent call last):
  File "/home/sadbhawna/anaconda3/lib/python3.11/site-packages/requests/adapters.py", line 486, in send
    resp = conn.urlopen(
           ^^^^^^^^^^^^^
  File "/home/sadbhawna/anaconda3/lib/python3.11/site-packages/urllib3/connectionpool.py", line 798, in urlopen
    retries = retries.increment(
              ^^^^^^^^^^^^^^^^^^
  File "/home/sadbhawna/anaconda3/lib/python3.11/site-packages/urllib3/util/retry.py", line 592, in increment
    raise MaxRetryError(_pool, url, error or ResponseError(cause))
urllib3.exceptions.MaxRetryError: HTTPSConnectionPool(host='api.wandb.ai', port=443): Max retries exceeded with url: /graphql (Caused by ConnectTimeoutError(<urllib3.connection.HTTPSConnection object at 0x7f9df5d026d0>, 'Connection to api.wandb.ai timed out. (connect timeout=20)'))

During handling of the above exception, another exception occurred:

Traceback (most recent call last):
  File "/home/sadbhawna/anaconda3/lib/python3.11/site-packages/wandb/sdk/lib/retry.py", line 131, in __call__
    result = self._call_fn(*args, **kwargs)
             ^^^^^^^^^^^^^^^^^^^^^^^^^^^^^^
  File "/home/sadbhawna/anaconda3/lib/python3.11/site-packages/wandb/sdk/internal/internal_api.py", line 369, in execute
    return self.client.execute(*args, **kwargs)  # type: ignore
           ^^^^^^^^^^^^^^^^^^^^^^^^^^^^^^^^^^^^
  File "/home/sadbhawna/anaconda3/lib/python3.11/site-packages/wandb/vendor/gql-0.2.0/wandb_gql/client.py", line 52, in execute
    result = self._get_result(document, *args, **kwargs)
             ^^^^^^^^^^^^^^^^^^^^^^^^^^^^^^^^^^^^^^^^^^^
  File "/home/sadbhawna/anaconda3/lib/python3.11/site-packages/wandb/vendor/gql-0.2.0/wandb_gql/client.py", line 60, in _get_result
    return self.transport.execute(document, *args, **kwargs)
           ^^^^^^^^^^^^^^^^^^^^^^^^^^^^^^^^^^^^^^^^^^^^^^^^^
  File "/home/sadbhawna/anaconda3/lib/python3.11/site-packages/wandb/sdk/lib/gql_request.py", line 58, in execute
    request = self.session.post(self.url, **post_args)
              ^^^^^^^^^^^^^^^^^^^^^^^^^^^^^^^^^^^^^^^^
  File "/home/sadbhawna/anaconda3/lib/python3.11/site-packages/requests/sessions.py", line 637, in post
    return self.request("POST", url, data=data, json=json, **kwargs)
           ^^^^^^^^^^^^^^^^^^^^^^^^^^^^^^^^^^^^^^^^^^^^^^^^^^^^^^^^^
  File "/home/sadbhawna/anaconda3/lib/python3.11/site-packages/requests/sessions.py", line 589, in request
    resp = self.send(prep, **send_kwargs)
           ^^^^^^^^^^^^^^^^^^^^^^^^^^^^^^
  File "/home/sadbhawna/anaconda3/lib/python3.11/site-packages/requests/sessions.py", line 703, in send
    r = adapter.send(request, **kwargs)
        ^^^^^^^^^^^^^^^^^^^^^^^^^^^^^^^
  File "/home/sadbhawna/anaconda3/lib/python3.11/site-packages/requests/adapters.py", line 507, in send
    raise ConnectTimeout(e, request=request)
requests.exceptions.ConnectTimeout: HTTPSConnectionPool(host='api.wandb.ai', port=443): Max retries exceeded with url: /graphql (Caused by ConnectTimeoutError(<urllib3.connection.HTTPSConnection object at 0x7f9df5d026d0>, 'Connection to api.wandb.ai timed out. (connect timeout=20)'))
2024-03-04 11:41:32,541 DEBUG   HandlerThread:6886 [handler.py:handle_request():146] handle_request: keepalive
2024-03-04 11:41:37,543 DEBUG   HandlerThread:6886 [handler.py:handle_request():146] handle_request: keepalive
2024-03-04 11:41:42,544 DEBUG   HandlerThread:6886 [handler.py:handle_request():146] handle_request: keepalive
2024-03-04 11:41:47,546 DEBUG   HandlerThread:6886 [handler.py:handle_request():146] handle_request: keepalive
2024-03-04 11:41:52,547 DEBUG   HandlerThread:6886 [handler.py:handle_request():146] handle_request: keepalive
2024-03-04 11:41:57,548 DEBUG   HandlerThread:6886 [handler.py:handle_request():146] handle_request: cancel
2024-03-04 11:41:57,549 DEBUG   HandlerThread:6886 [handler.py:handle_request():146] handle_request: cancel
2024-03-04 11:41:57,549 DEBUG   SenderThread:6886 [sender.py:send():391] Record cancelled: run
2024-03-04 11:41:57,550 DEBUG   HandlerThread:6886 [handler.py:handle_request():146] handle_request: status_report
2024-03-04 11:42:02,551 DEBUG   HandlerThread:6886 [handler.py:handle_request():146] handle_request: status_report
2024-03-04 11:42:07,551 DEBUG   HandlerThread:6886 [handler.py:handle_request():146] handle_request: status_report
2024-03-04 11:42:09,560 DEBUG   HandlerThread:6886 [handler.py:handle_request():146] handle_request: shutdown
2024-03-04 11:42:09,560 INFO    HandlerThread:6886 [handler.py:finish():869] shutting down handler
2024-03-04 11:42:10,552 INFO    SenderThread:6886 [sender.py:finish():1572] shutting down sender
2024-03-04 11:42:10,552 INFO    WriterThread:6886 [datastore.py:close():296] close: /home/sadbhawna/Desktop/cs6910_assignment1/wandb/run-20240304_114027-g770qtjx/run-g770qtjx.wandb
