2024-02-27 09:37:55,342 INFO    StreamThr :8780 [internal.py:wandb_internal():86] W&B internal server running at pid: 8780, started at: 2024-02-27 09:37:55.341689
2024-02-27 09:37:55,344 DEBUG   HandlerThread:8780 [handler.py:handle_request():146] handle_request: status
2024-02-27 09:37:55,345 INFO    WriterThread:8780 [datastore.py:open_for_write():87] open: /home/sadbhawna/Desktop/cs6910_assignment1/wandb/run-20240227_093755-p85fpbhq/run-p85fpbhq.wandb
2024-02-27 09:37:55,347 DEBUG   SenderThread:8780 [sender.py:send():382] send: header
2024-02-27 09:37:55,347 DEBUG   SenderThread:8780 [sender.py:send():382] send: run
2024-02-27 09:37:58,913 INFO    SenderThread:8780 [retry.py:__call__():172] Retry attempt failed:
Traceback (most recent call last):
  File "/home/sadbhawna/anaconda3/lib/python3.11/site-packages/urllib3/connection.py", line 174, in _new_conn
    conn = connection.create_connection(
           ^^^^^^^^^^^^^^^^^^^^^^^^^^^^^
  File "/home/sadbhawna/anaconda3/lib/python3.11/site-packages/urllib3/util/connection.py", line 72, in create_connection
    for res in socket.getaddrinfo(host, port, family, socket.SOCK_STREAM):
               ^^^^^^^^^^^^^^^^^^^^^^^^^^^^^^^^^^^^^^^^^^^^^^^^^^^^^^^^^^
  File "/home/sadbhawna/anaconda3/lib/python3.11/socket.py", line 962, in getaddrinfo
    for res in _socket.getaddrinfo(host, port, family, type, proto, flags):
               ^^^^^^^^^^^^^^^^^^^^^^^^^^^^^^^^^^^^^^^^^^^^^^^^^^^^^^^^^^^
socket.gaierror: [Errno -2] Name or service not known

During handling of the above exception, another exception occurred:

Traceback (most recent call last):
  File "/home/sadbhawna/anaconda3/lib/python3.11/site-packages/urllib3/connectionpool.py", line 714, in urlopen
    httplib_response = self._make_request(
                       ^^^^^^^^^^^^^^^^^^^
  File "/home/sadbhawna/anaconda3/lib/python3.11/site-packages/urllib3/connectionpool.py", line 403, in _make_request
    self._validate_conn(conn)
  File "/home/sadbhawna/anaconda3/lib/python3.11/site-packages/urllib3/connectionpool.py", line 1053, in _validate_conn
    conn.connect()
  File "/home/sadbhawna/anaconda3/lib/python3.11/site-packages/urllib3/connection.py", line 363, in connect
    self.sock = conn = self._new_conn()
                       ^^^^^^^^^^^^^^^^
  File "/home/sadbhawna/anaconda3/lib/python3.11/site-packages/urllib3/connection.py", line 186, in _new_conn
    raise NewConnectionError(
urllib3.exceptions.NewConnectionError: <urllib3.connection.HTTPSConnection object at 0x7f78cea530d0>: Failed to establish a new connection: [Errno -2] Name or service not known

During handling of the above exception, another exception occurred:

Traceback (most recent call last):
  File "/home/sadbhawna/anaconda3/lib/python3.11/site-packages/requests/adapters.py", line 486, in send
    resp = conn.urlopen(
           ^^^^^^^^^^^^^
  File "/home/sadbhawna/anaconda3/lib/python3.11/site-packages/urllib3/connectionpool.py", line 798, in urlopen
    retries = retries.increment(
              ^^^^^^^^^^^^^^^^^^
  File "/home/sadbhawna/anaconda3/lib/python3.11/site-packages/urllib3/util/retry.py", line 592, in increment
    raise MaxRetryError(_pool, url, error or ResponseError(cause))
urllib3.exceptions.MaxRetryError: HTTPSConnectionPool(host='api.wandb.ai', port=443): Max retries exceeded with url: /graphql (Caused by NewConnectionError('<urllib3.connection.HTTPSConnection object at 0x7f78cea530d0>: Failed to establish a new connection: [Errno -2] Name or service not known'))

During handling of the above exception, another exception occurred:

Traceback (most recent call last):
  File "/home/sadbhawna/anaconda3/lib/python3.11/site-packages/wandb/sdk/lib/retry.py", line 131, in __call__
    result = self._call_fn(*args, **kwargs)
             ^^^^^^^^^^^^^^^^^^^^^^^^^^^^^^
  File "/home/sadbhawna/anaconda3/lib/python3.11/site-packages/wandb/sdk/internal/internal_api.py", line 369, in execute
    return self.client.execute(*args, **kwargs)  # type: ignore
           ^^^^^^^^^^^^^^^^^^^^^^^^^^^^^^^^^^^^
  File "/home/sadbhawna/anaconda3/lib/python3.11/site-packages/wandb/vendor/gql-0.2.0/wandb_gql/client.py", line 52, in execute
    result = self._get_result(document, *args, **kwargs)
             ^^^^^^^^^^^^^^^^^^^^^^^^^^^^^^^^^^^^^^^^^^^
  File "/home/sadbhawna/anaconda3/lib/python3.11/site-packages/wandb/vendor/gql-0.2.0/wandb_gql/client.py", line 60, in _get_result
    return self.transport.execute(document, *args, **kwargs)
           ^^^^^^^^^^^^^^^^^^^^^^^^^^^^^^^^^^^^^^^^^^^^^^^^^
  File "/home/sadbhawna/anaconda3/lib/python3.11/site-packages/wandb/sdk/lib/gql_request.py", line 58, in execute
    request = self.session.post(self.url, **post_args)
              ^^^^^^^^^^^^^^^^^^^^^^^^^^^^^^^^^^^^^^^^
  File "/home/sadbhawna/anaconda3/lib/python3.11/site-packages/requests/sessions.py", line 637, in post
    return self.request("POST", url, data=data, json=json, **kwargs)
           ^^^^^^^^^^^^^^^^^^^^^^^^^^^^^^^^^^^^^^^^^^^^^^^^^^^^^^^^^
  File "/home/sadbhawna/anaconda3/lib/python3.11/site-packages/requests/sessions.py", line 589, in request
    resp = self.send(prep, **send_kwargs)
           ^^^^^^^^^^^^^^^^^^^^^^^^^^^^^^
  File "/home/sadbhawna/anaconda3/lib/python3.11/site-packages/requests/sessions.py", line 703, in send
    r = adapter.send(request, **kwargs)
        ^^^^^^^^^^^^^^^^^^^^^^^^^^^^^^^
  File "/home/sadbhawna/anaconda3/lib/python3.11/site-packages/requests/adapters.py", line 519, in send
    raise ConnectionError(e, request=request)
requests.exceptions.ConnectionError: HTTPSConnectionPool(host='api.wandb.ai', port=443): Max retries exceeded with url: /graphql (Caused by NewConnectionError('<urllib3.connection.HTTPSConnection object at 0x7f78cea530d0>: Failed to establish a new connection: [Errno -2] Name or service not known'))
2024-02-27 09:38:00,348 DEBUG   HandlerThread:8780 [handler.py:handle_request():146] handle_request: keepalive
2024-02-27 09:38:05,349 DEBUG   HandlerThread:8780 [handler.py:handle_request():146] handle_request: keepalive
2024-02-27 09:38:10,350 DEBUG   HandlerThread:8780 [handler.py:handle_request():146] handle_request: keepalive
2024-02-27 09:38:15,352 DEBUG   HandlerThread:8780 [handler.py:handle_request():146] handle_request: keepalive
2024-02-27 09:38:20,353 DEBUG   HandlerThread:8780 [handler.py:handle_request():146] handle_request: keepalive
2024-02-27 09:38:25,354 DEBUG   HandlerThread:8780 [handler.py:handle_request():146] handle_request: keepalive
2024-02-27 09:38:26,485 DEBUG   HandlerThread:8780 [handler.py:handle_request():146] handle_request: shutdown
2024-02-27 09:38:26,486 INFO    HandlerThread:8780 [handler.py:finish():869] shutting down handler
2024-02-27 09:38:27,350 INFO    WriterThread:8780 [datastore.py:close():296] close: /home/sadbhawna/Desktop/cs6910_assignment1/wandb/run-20240227_093755-p85fpbhq/run-p85fpbhq.wandb
2024-02-27 09:40:16,859 INFO    SenderThread:8780 [dir_watcher.py:__init__():211] watching files in: /home/sadbhawna/Desktop/cs6910_assignment1/wandb/run-20240227_093755-p85fpbhq/files
2024-02-27 09:40:16,860 INFO    SenderThread:8780 [sender.py:_start_run_threads():1136] run started: p85fpbhq with start time 1709006875.341366
2024-02-27 09:40:16,860 INFO    SenderThread:8780 [sender.py:finish():1572] shutting down sender
2024-02-27 09:40:16,860 INFO    SenderThread:8780 [dir_watcher.py:finish():358] shutting down directory watcher
2024-02-27 09:40:17,860 INFO    SenderThread:8780 [dir_watcher.py:finish():388] scan: /home/sadbhawna/Desktop/cs6910_assignment1/wandb/run-20240227_093755-p85fpbhq/files
2024-02-27 09:40:17,861 INFO    SenderThread:8780 [dir_watcher.py:finish():402] scan save: /home/sadbhawna/Desktop/cs6910_assignment1/wandb/run-20240227_093755-p85fpbhq/files/config.yaml config.yaml
2024-02-27 09:40:17,861 INFO    SenderThread:8780 [file_pusher.py:finish():172] shutting down file pusher
2024-02-27 09:40:17,861 INFO    SenderThread:8780 [file_pusher.py:join():178] waiting for file pusher
2024-02-27 09:40:18,786 INFO    wandb-upload_0:8780 [upload_job.py:push():131] Uploaded file /home/sadbhawna/Desktop/cs6910_assignment1/wandb/run-20240227_093755-p85fpbhq/files/config.yaml
2024-02-27 09:40:19,366 INFO    SenderThread:8780 [file_stream.py:finish():595] file stream finish called
2024-02-27 09:40:19,671 INFO    SenderThread:8780 [file_stream.py:finish():599] file stream finish is done
