Traceback (most recent call last):
  File "/home/sadbhawna/anaconda3/lib/python3.11/site-packages/wandb/sdk/wandb_config.py", line 162, in __getattr__
    return self.__getitem__(key)
           ^^^^^^^^^^^^^^^^^^^^^
  File "/home/sadbhawna/anaconda3/lib/python3.11/site-packages/wandb/sdk/wandb_config.py", line 130, in __getitem__
    return self._items[key]
           ~~~~~~~~~~~^^^^^
KeyError: 'wandb_project'
The above exception was the direct cause of the following exception:
Traceback (most recent call last):
  File "/home/sadbhawna/Desktop/cs6910_assignment1/sweep_functionality.py", line 93, in train
    weight_decay=config.weight_decay, epsilon=config.eps, project=config.wandb_project)
                                                                  ^^^^^^^^^^^^^^^^^^^^
  File "/home/sadbhawna/anaconda3/lib/python3.11/site-packages/wandb/sdk/wandb_config.py", line 164, in __getattr__
    raise AttributeError(
AttributeError: <class 'wandb.sdk.wandb_config.Config'> object has no attribute 'wandb_project'