2024-03-04 11:42:19,329 INFO    StreamThr :7406 [internal.py:wandb_internal():86] W&B internal server running at pid: 7406, started at: 2024-03-04 11:42:19.329104
2024-03-04 11:42:19,333 DEBUG   HandlerThread:7406 [handler.py:handle_request():146] handle_request: status
2024-03-04 11:42:19,338 INFO    WriterThread:7406 [datastore.py:open_for_write():87] open: /home/sadbhawna/Desktop/cs6910_assignment1/wandb/run-20240304_114219-vn2wamm8/run-vn2wamm8.wandb
2024-03-04 11:42:19,338 DEBUG   SenderThread:7406 [sender.py:send():382] send: header
2024-03-04 11:42:19,344 DEBUG   SenderThread:7406 [sender.py:send():382] send: run
2024-03-04 11:42:24,345 DEBUG   HandlerThread:7406 [handler.py:handle_request():146] handle_request: keepalive
2024-03-04 11:42:29,346 DEBUG   HandlerThread:7406 [handler.py:handle_request():146] handle_request: keepalive
2024-03-04 11:42:34,348 DEBUG   HandlerThread:7406 [handler.py:handle_request():146] handle_request: keepalive
2024-03-04 11:42:39,349 DEBUG   HandlerThread:7406 [handler.py:handle_request():146] handle_request: keepalive
2024-03-04 11:42:44,351 DEBUG   HandlerThread:7406 [handler.py:handle_request():146] handle_request: keepalive
2024-03-04 11:42:49,352 DEBUG   HandlerThread:7406 [handler.py:handle_request():146] handle_request: keepalive
2024-03-04 11:42:54,354 DEBUG   HandlerThread:7406 [handler.py:handle_request():146] handle_request: keepalive
2024-03-04 11:42:59,355 DEBUG   HandlerThread:7406 [handler.py:handle_request():146] handle_request: keepalive
2024-03-04 11:43:04,357 DEBUG   HandlerThread:7406 [handler.py:handle_request():146] handle_request: keepalive
2024-03-04 11:43:09,358 DEBUG   HandlerThread:7406 [handler.py:handle_request():146] handle_request: keepalive
2024-03-04 11:43:14,360 DEBUG   HandlerThread:7406 [handler.py:handle_request():146] handle_request: keepalive
2024-03-04 11:43:19,361 DEBUG   HandlerThread:7406 [handler.py:handle_request():146] handle_request: keepalive
2024-03-04 11:43:22,969 INFO    SenderThread:7406 [retry.py:__call__():172] Retry attempt failed:
Traceback (most recent call last):
  File "/home/sadbhawna/anaconda3/lib/python3.11/site-packages/urllib3/connection.py", line 174, in _new_conn
    conn = connection.create_connection(
           ^^^^^^^^^^^^^^^^^^^^^^^^^^^^^
  File "/home/sadbhawna/anaconda3/lib/python3.11/site-packages/urllib3/util/connection.py", line 95, in create_connection
    raise err
  File "/home/sadbhawna/anaconda3/lib/python3.11/site-packages/urllib3/util/connection.py", line 85, in create_connection
    sock.connect(sa)
TimeoutError: timed out

During handling of the above exception, another exception occurred:

Traceback (most recent call last):
  File "/home/sadbhawna/anaconda3/lib/python3.11/site-packages/urllib3/connectionpool.py", line 714, in urlopen
    httplib_response = self._make_request(
                       ^^^^^^^^^^^^^^^^^^^
  File "/home/sadbhawna/anaconda3/lib/python3.11/site-packages/urllib3/connectionpool.py", line 403, in _make_request
    self._validate_conn(conn)
  File "/home/sadbhawna/anaconda3/lib/python3.11/site-packages/urllib3/connectionpool.py", line 1053, in _validate_conn
    conn.connect()
  File "/home/sadbhawna/anaconda3/lib/python3.11/site-packages/urllib3/connection.py", line 363, in connect
    self.sock = conn = self._new_conn()
                       ^^^^^^^^^^^^^^^^
  File "/home/sadbhawna/anaconda3/lib/python3.11/site-packages/urllib3/connection.py", line 179, in _new_conn
    raise ConnectTimeoutError(
urllib3.exceptions.ConnectTimeoutError: (<urllib3.connection.HTTPSConnection object at 0x7fe3738c5fd0>, 'Connection to api.wandb.ai timed out. (connect timeout=20)')

During handling of the above exception, another exception occurred:

Traceback (most recent call last):
  File "/home/sadbhawna/anaconda3/lib/python3.11/site-packages/requests/adapters.py", line 486, in send
    resp = conn.urlopen(
           ^^^^^^^^^^^^^
  File "/home/sadbhawna/anaconda3/lib/python3.11/site-packages/urllib3/connectionpool.py", line 798, in urlopen
    retries = retries.increment(
              ^^^^^^^^^^^^^^^^^^
  File "/home/sadbhawna/anaconda3/lib/python3.11/site-packages/urllib3/util/retry.py", line 592, in increment
    raise MaxRetryError(_pool, url, error or ResponseError(cause))
urllib3.exceptions.MaxRetryError: HTTPSConnectionPool(host='api.wandb.ai', port=443): Max retries exceeded with url: /graphql (Caused by ConnectTimeoutError(<urllib3.connection.HTTPSConnection object at 0x7fe3738c5fd0>, 'Connection to api.wandb.ai timed out. (connect timeout=20)'))

During handling of the above exception, another exception occurred:

Traceback (most recent call last):
  File "/home/sadbhawna/anaconda3/lib/python3.11/site-packages/wandb/sdk/lib/retry.py", line 131, in __call__
    result = self._call_fn(*args, **kwargs)
             ^^^^^^^^^^^^^^^^^^^^^^^^^^^^^^
  File "/home/sadbhawna/anaconda3/lib/python3.11/site-packages/wandb/sdk/internal/internal_api.py", line 369, in execute
    return self.client.execute(*args, **kwargs)  # type: ignore
           ^^^^^^^^^^^^^^^^^^^^^^^^^^^^^^^^^^^^
  File "/home/sadbhawna/anaconda3/lib/python3.11/site-packages/wandb/vendor/gql-0.2.0/wandb_gql/client.py", line 52, in execute
    result = self._get_result(document, *args, **kwargs)
             ^^^^^^^^^^^^^^^^^^^^^^^^^^^^^^^^^^^^^^^^^^^
  File "/home/sadbhawna/anaconda3/lib/python3.11/site-packages/wandb/vendor/gql-0.2.0/wandb_gql/client.py", line 60, in _get_result
    return self.transport.execute(document, *args, **kwargs)
           ^^^^^^^^^^^^^^^^^^^^^^^^^^^^^^^^^^^^^^^^^^^^^^^^^
  File "/home/sadbhawna/anaconda3/lib/python3.11/site-packages/wandb/sdk/lib/gql_request.py", line 58, in execute
    request = self.session.post(self.url, **post_args)
              ^^^^^^^^^^^^^^^^^^^^^^^^^^^^^^^^^^^^^^^^
  File "/home/sadbhawna/anaconda3/lib/python3.11/site-packages/requests/sessions.py", line 637, in post
    return self.request("POST", url, data=data, json=json, **kwargs)
           ^^^^^^^^^^^^^^^^^^^^^^^^^^^^^^^^^^^^^^^^^^^^^^^^^^^^^^^^^
  File "/home/sadbhawna/anaconda3/lib/python3.11/site-packages/requests/sessions.py", line 589, in request
    resp = self.send(prep, **send_kwargs)
           ^^^^^^^^^^^^^^^^^^^^^^^^^^^^^^
  File "/home/sadbhawna/anaconda3/lib/python3.11/site-packages/requests/sessions.py", line 703, in send
    r = adapter.send(request, **kwargs)
        ^^^^^^^^^^^^^^^^^^^^^^^^^^^^^^^
  File "/home/sadbhawna/anaconda3/lib/python3.11/site-packages/requests/adapters.py", line 507, in send
    raise ConnectTimeout(e, request=request)
requests.exceptions.ConnectTimeout: HTTPSConnectionPool(host='api.wandb.ai', port=443): Max retries exceeded with url: /graphql (Caused by ConnectTimeoutError(<urllib3.connection.HTTPSConnection object at 0x7fe3738c5fd0>, 'Connection to api.wandb.ai timed out. (connect timeout=20)'))
2024-03-04 11:43:24,363 DEBUG   HandlerThread:7406 [handler.py:handle_request():146] handle_request: keepalive
2024-03-04 11:43:29,364 DEBUG   HandlerThread:7406 [handler.py:handle_request():146] handle_request: keepalive
2024-03-04 11:43:34,366 DEBUG   HandlerThread:7406 [handler.py:handle_request():146] handle_request: keepalive
2024-03-04 11:43:39,367 DEBUG   HandlerThread:7406 [handler.py:handle_request():146] handle_request: keepalive
2024-03-04 11:43:44,369 DEBUG   HandlerThread:7406 [handler.py:handle_request():146] handle_request: keepalive
2024-03-04 11:43:49,370 DEBUG   HandlerThread:7406 [handler.py:handle_request():146] handle_request: cancel
2024-03-04 11:43:49,371 DEBUG   HandlerThread:7406 [handler.py:handle_request():146] handle_request: cancel
2024-03-04 11:43:49,371 DEBUG   SenderThread:7406 [sender.py:send():391] Record cancelled: run
2024-03-04 11:43:49,371 DEBUG   HandlerThread:7406 [handler.py:handle_request():146] handle_request: status_report
2024-03-04 11:43:54,372 DEBUG   HandlerThread:7406 [handler.py:handle_request():146] handle_request: status_report
2024-03-04 11:43:56,154 DEBUG   HandlerThread:7406 [handler.py:handle_request():146] handle_request: shutdown
2024-03-04 11:43:56,154 INFO    HandlerThread:7406 [handler.py:finish():869] shutting down handler
2024-03-04 11:43:56,373 INFO    SenderThread:7406 [sender.py:finish():1572] shutting down sender
2024-03-04 11:43:56,374 INFO    WriterThread:7406 [datastore.py:close():296] close: /home/sadbhawna/Desktop/cs6910_assignment1/wandb/run-20240304_114219-vn2wamm8/run-vn2wamm8.wandb
