2024-03-04 11:38:44,716 INFO    StreamThr :6555 [internal.py:wandb_internal():86] W&B internal server running at pid: 6555, started at: 2024-03-04 11:38:44.715725
2024-03-04 11:38:44,720 DEBUG   HandlerThread:6555 [handler.py:handle_request():146] handle_request: status
2024-03-04 11:38:44,726 INFO    WriterThread:6555 [datastore.py:open_for_write():87] open: /home/sadbhawna/Desktop/cs6910_assignment1/wandb/run-20240304_113844-0q0vppav/run-0q0vppav.wandb
2024-03-04 11:38:44,727 DEBUG   SenderThread:6555 [sender.py:send():382] send: header
2024-03-04 11:38:44,732 DEBUG   SenderThread:6555 [sender.py:send():382] send: run
2024-03-04 11:38:49,733 DEBUG   HandlerThread:6555 [handler.py:handle_request():146] handle_request: keepalive
2024-03-04 11:38:54,735 DEBUG   HandlerThread:6555 [handler.py:handle_request():146] handle_request: keepalive
2024-03-04 11:38:59,736 DEBUG   HandlerThread:6555 [handler.py:handle_request():146] handle_request: keepalive
2024-03-04 11:39:04,738 DEBUG   HandlerThread:6555 [handler.py:handle_request():146] handle_request: keepalive
2024-03-04 11:39:09,739 DEBUG   HandlerThread:6555 [handler.py:handle_request():146] handle_request: keepalive
2024-03-04 11:39:14,741 DEBUG   HandlerThread:6555 [handler.py:handle_request():146] handle_request: keepalive
2024-03-04 11:39:19,742 DEBUG   HandlerThread:6555 [handler.py:handle_request():146] handle_request: keepalive
2024-03-04 11:39:24,744 DEBUG   HandlerThread:6555 [handler.py:handle_request():146] handle_request: keepalive
2024-03-04 11:39:29,745 DEBUG   HandlerThread:6555 [handler.py:handle_request():146] handle_request: keepalive
2024-03-04 11:39:34,746 DEBUG   HandlerThread:6555 [handler.py:handle_request():146] handle_request: keepalive
2024-03-04 11:39:39,748 DEBUG   HandlerThread:6555 [handler.py:handle_request():146] handle_request: keepalive
2024-03-04 11:39:44,750 DEBUG   HandlerThread:6555 [handler.py:handle_request():146] handle_request: keepalive
2024-03-04 11:39:48,228 INFO    SenderThread:6555 [retry.py:__call__():172] Retry attempt failed:
Traceback (most recent call last):
  File "/home/sadbhawna/anaconda3/lib/python3.11/site-packages/urllib3/connection.py", line 174, in _new_conn
    conn = connection.create_connection(
           ^^^^^^^^^^^^^^^^^^^^^^^^^^^^^
  File "/home/sadbhawna/anaconda3/lib/python3.11/site-packages/urllib3/util/connection.py", line 95, in create_connection
    raise err
  File "/home/sadbhawna/anaconda3/lib/python3.11/site-packages/urllib3/util/connection.py", line 85, in create_connection
    sock.connect(sa)
TimeoutError: timed out

During handling of the above exception, another exception occurred:

Traceback (most recent call last):
  File "/home/sadbhawna/anaconda3/lib/python3.11/site-packages/urllib3/connectionpool.py", line 714, in urlopen
    httplib_response = self._make_request(
                       ^^^^^^^^^^^^^^^^^^^
  File "/home/sadbhawna/anaconda3/lib/python3.11/site-packages/urllib3/connectionpool.py", line 403, in _make_request
    self._validate_conn(conn)
  File "/home/sadbhawna/anaconda3/lib/python3.11/site-packages/urllib3/connectionpool.py", line 1053, in _validate_conn
    conn.connect()
  File "/home/sadbhawna/anaconda3/lib/python3.11/site-packages/urllib3/connection.py", line 363, in connect
    self.sock = conn = self._new_conn()
                       ^^^^^^^^^^^^^^^^
  File "/home/sadbhawna/anaconda3/lib/python3.11/site-packages/urllib3/connection.py", line 179, in _new_conn
    raise ConnectTimeoutError(
urllib3.exceptions.ConnectTimeoutError: (<urllib3.connection.HTTPSConnection object at 0x7f6e0f992290>, 'Connection to api.wandb.ai timed out. (connect timeout=20)')

During handling of the above exception, another exception occurred:

Traceback (most recent call last):
  File "/home/sadbhawna/anaconda3/lib/python3.11/site-packages/requests/adapters.py", line 486, in send
    resp = conn.urlopen(
           ^^^^^^^^^^^^^
  File "/home/sadbhawna/anaconda3/lib/python3.11/site-packages/urllib3/connectionpool.py", line 798, in urlopen
    retries = retries.increment(
              ^^^^^^^^^^^^^^^^^^
  File "/home/sadbhawna/anaconda3/lib/python3.11/site-packages/urllib3/util/retry.py", line 592, in increment
    raise MaxRetryError(_pool, url, error or ResponseError(cause))
urllib3.exceptions.MaxRetryError: HTTPSConnectionPool(host='api.wandb.ai', port=443): Max retries exceeded with url: /graphql (Caused by ConnectTimeoutError(<urllib3.connection.HTTPSConnection object at 0x7f6e0f992290>, 'Connection to api.wandb.ai timed out. (connect timeout=20)'))

During handling of the above exception, another exception occurred:

Traceback (most recent call last):
  File "/home/sadbhawna/anaconda3/lib/python3.11/site-packages/wandb/sdk/lib/retry.py", line 131, in __call__
    result = self._call_fn(*args, **kwargs)
             ^^^^^^^^^^^^^^^^^^^^^^^^^^^^^^
  File "/home/sadbhawna/anaconda3/lib/python3.11/site-packages/wandb/sdk/internal/internal_api.py", line 369, in execute
    return self.client.execute(*args, **kwargs)  # type: ignore
           ^^^^^^^^^^^^^^^^^^^^^^^^^^^^^^^^^^^^
  File "/home/sadbhawna/anaconda3/lib/python3.11/site-packages/wandb/vendor/gql-0.2.0/wandb_gql/client.py", line 52, in execute
    result = self._get_result(document, *args, **kwargs)
             ^^^^^^^^^^^^^^^^^^^^^^^^^^^^^^^^^^^^^^^^^^^
  File "/home/sadbhawna/anaconda3/lib/python3.11/site-packages/wandb/vendor/gql-0.2.0/wandb_gql/client.py", line 60, in _get_result
    return self.transport.execute(document, *args, **kwargs)
           ^^^^^^^^^^^^^^^^^^^^^^^^^^^^^^^^^^^^^^^^^^^^^^^^^
  File "/home/sadbhawna/anaconda3/lib/python3.11/site-packages/wandb/sdk/lib/gql_request.py", line 58, in execute
    request = self.session.post(self.url, **post_args)
              ^^^^^^^^^^^^^^^^^^^^^^^^^^^^^^^^^^^^^^^^
  File "/home/sadbhawna/anaconda3/lib/python3.11/site-packages/requests/sessions.py", line 637, in post
    return self.request("POST", url, data=data, json=json, **kwargs)
           ^^^^^^^^^^^^^^^^^^^^^^^^^^^^^^^^^^^^^^^^^^^^^^^^^^^^^^^^^
  File "/home/sadbhawna/anaconda3/lib/python3.11/site-packages/requests/sessions.py", line 589, in request
    resp = self.send(prep, **send_kwargs)
           ^^^^^^^^^^^^^^^^^^^^^^^^^^^^^^
  File "/home/sadbhawna/anaconda3/lib/python3.11/site-packages/requests/sessions.py", line 703, in send
    r = adapter.send(request, **kwargs)
        ^^^^^^^^^^^^^^^^^^^^^^^^^^^^^^^
  File "/home/sadbhawna/anaconda3/lib/python3.11/site-packages/requests/adapters.py", line 507, in send
    raise ConnectTimeout(e, request=request)
requests.exceptions.ConnectTimeout: HTTPSConnectionPool(host='api.wandb.ai', port=443): Max retries exceeded with url: /graphql (Caused by ConnectTimeoutError(<urllib3.connection.HTTPSConnection object at 0x7f6e0f992290>, 'Connection to api.wandb.ai timed out. (connect timeout=20)'))
2024-03-04 11:39:49,751 DEBUG   HandlerThread:6555 [handler.py:handle_request():146] handle_request: keepalive
2024-03-04 11:39:54,753 DEBUG   HandlerThread:6555 [handler.py:handle_request():146] handle_request: keepalive
2024-03-04 11:39:59,754 DEBUG   HandlerThread:6555 [handler.py:handle_request():146] handle_request: keepalive
2024-03-04 11:40:04,755 DEBUG   HandlerThread:6555 [handler.py:handle_request():146] handle_request: keepalive
2024-03-04 11:40:09,757 DEBUG   HandlerThread:6555 [handler.py:handle_request():146] handle_request: keepalive
2024-03-04 11:40:14,758 DEBUG   HandlerThread:6555 [handler.py:handle_request():146] handle_request: cancel
2024-03-04 11:40:14,759 DEBUG   HandlerThread:6555 [handler.py:handle_request():146] handle_request: cancel
2024-03-04 11:40:14,759 DEBUG   SenderThread:6555 [sender.py:send():391] Record cancelled: run
2024-03-04 11:40:14,759 DEBUG   HandlerThread:6555 [handler.py:handle_request():146] handle_request: status_report
2024-03-04 11:40:18,530 DEBUG   HandlerThread:6555 [handler.py:handle_request():146] handle_request: shutdown
2024-03-04 11:40:18,530 INFO    HandlerThread:6555 [handler.py:finish():869] shutting down handler
2024-03-04 11:40:18,760 INFO    SenderThread:6555 [sender.py:finish():1572] shutting down sender
2024-03-04 11:40:18,761 INFO    WriterThread:6555 [datastore.py:close():296] close: /home/sadbhawna/Desktop/cs6910_assignment1/wandb/run-20240304_113844-0q0vppav/run-0q0vppav.wandb
